Workbook

Sheet Summary
A1: BP plc | DCF Valuation | L1: Year | M1: UFCF
A2: Independent valuation analysis | Public information through 4 September 2026 | GBX / US$ million unless stated | L2: 2026E | M2: =Forecast!F48 -> 12657.783
L3: 2027E | M3: =Forecast!G48 -> 13884.253
A4: VALUATION SNAPSHOT | F4: OPERATING SNAPSHOT | L4: 2028E | M4: =Forecast!H48 -> 12589.171
A5: Metric | B5: Value | C5: Unit | D5: Reference | F5: Metric | G5: 2026E | H5: 2030E | I5: Unit | J5: Source | L5: 2029E | M5: =Forecast!I48 -> 13450.78
A6: Implied share value | B6: =DCF!C57 -> 739.28221 | C6: GBX | D6: Base case | F6: Brent average price | G6: =Forecast!F7 -> 87 | H6: =Forecast!J7 -> 74.838251 | I6: $/bbl | J6: Forecast | L6: 2030E | M6: =Forecast!J48 -> 15205.398
A7: Market price | B7: =DCF!C58 -> 539.7 | C7: GBX | D7: 4-Sep-2026 | F7: Oil P&O production | G7: =Forecast!F8 -> 1504.1315 | H7: =Forecast!J8 -> 1613.601 | I7: mboe/d | J7: Forecast
A8: Upside / (downside) | B8: =DCF!C59 -> 0.36980212 | C8: % | D8: Base vs market | F8: Gas & LCE production | G8: =Forecast!F10 -> 720.86849 | H8: =Forecast!J10 -> 731.33733 | I8: mboe/d | J8: Forecast | L8: Valuation | M8: GBX
A9: Operating enterprise value | B9: =DCF!C33 -> 223978.97 | C9: $m | D9: DCF | F9: Group underlying RC PBIT | G9: =Forecast!F31 -> 30131.812 | H9: =Forecast!J31 -> 24689.341 | I9: $m | J9: Forecast | L9: Market | M9: =DCF!C58 -> 539.7
A10: Implied ordinary equity value | B10: =DCF!C51 -> 158383.58 | C10: $m | D10: EV bridge | F10: Unlevered free cash flow | G10: =Forecast!F48 -> 12657.783 | H10: =Forecast!J48 -> 15205.398 | I10: $m | J10: Forecast | L10: Implied | M10: =DCF!C57 -> 739.28221
A11: WACC | B11: =DCF!C18 -> 0.070552974 | C11: % | D11: Calculated | F11: UFCF / sales | G11: =Forecast!F49 -> 0.054877873 | H11: =Forecast!J49 -> 0.076636041 | I11: % | J11: Forecast
A12: Perpetual growth | B12: =DCF!C17 -> 0.015 | C12: % | D12: Terminal | F12: PV terminal value / EV | G12: =DCF!C34 -> 0.76704265 | H12: =DCF!C34 -> 0.76704265 | I12: % | J12: DCF
A15: OPERATING SCENARIOS | F15: KEY CHECKS
A16: Case | B16: Implied value | C16: Upside / (downside) | D16: Key framing | F16: Check | I16: Status
A17: Bear | B17: =Sensitivity!L16 -> 515.18771 | C17: =Sensitivity!L17 -> -0.04541836 | D17: Commodity / delivery downside | F17: WACC > perpetual growth | I17: =IF(DCF!C18>DCF!C17,"OK","CHECK") -> OK
A18: Base | B18: =Sensitivity!M16 -> 739.28221 | C18: =Sensitivity!M17 -> 0.36980212 | D18: Central assumptions | F18: Base sensitivity ties to DCF | I18: =IF(ABS(Sensitivity!E9-DCF!C57)<0.01,"OK","CHECK") -> OK
A19: Bull | B19: =Sensitivity!N16 -> 950.63021 | C19: =Sensitivity!N17 -> 0.76140487 | D19: Commodity / delivery upside | F19: Base scenario ties to DCF | I19: =IF(ABS(Sensitivity!M16-DCF!C57)<0.01,"OK","CHECK") -> OK

Sheet Assumptions
A1: BP plc | Key Assumptions
A2: Base-case operating, WACC and equity-bridge inputs | USD unless stated
A4: MARKET & OPERATING DRIVERS
A5: Driver / Assumption | B5: Unit | C5: 2026E | D5: 2027E | E5: 2028E | F5: 2029E | G5: 2030E | H5: Source
A6: Sales / working-capital proxy | B6: $m | C6: 230653.66 | D6: 182932.22 | E6: 178489.94 | F6: 189809.61 | G6: 198410.54 | H6: S02/S19
A7: Brent average price | B7: $/bbl | C7: 87 | D7: 69 | E7: 67.324422 | F7: 71.594075 | G7: 74.838251 | H7: S04/S17
A8: Oil total realisation / Brent | B8: % | C8: 0.69142912 | D8: 0.69142912 | E8: 0.69142912 | F8: 0.69142912 | G8: 0.69142912 | H8: S01
A9: Oil P&O production | B9: mboe/d | C9: 1504.1315 | D9: 1498.6238 | E9: 1502.7874 | F9: 1543.3783 | G9: 1613.601 | H9: S02/S05
A10: Oil adjusted EBITDA conversion | B10: % | C10: 0.65322904 | D10: 0.649 | E10: 0.649 | F10: 0.649 | G10: 0.649 | H10: S01/S02
A11: Oil D&A / boe | B11: $/boe | C11: 13.986171 | D11: 14 | E11: 14 | F11: 14 | G11: 14 | H11: S01/S02
A12: Oil exploration write-offs | B12: $m | C12: 660 | D12: 400 | E12: 400 | F12: 400 | G12: 400 | H12: S02/S19
A13: Henry Hub | B13: $/mcf | C13: 3.56728 | D13: 3.43247 | E13: 4.07541 | F13: 4.34503 | G13: 5.17463 | H13: S04/S17
A14: Gas premium to Henry Hub | B14: $/mcf | C14: 3.3617067 | D14: 3.3617067 | E14: 3.3617067 | F14: 3.3617067 | G14: 3.3617067 | H14: S01
A15: Gas liquids production mix | B15: % | C15: 0.11 | D15: 0.11 | E15: 0.11 | F15: 0.11 | G15: 0.11 | H15: S01
A16: Gas conversion | B16: mcf/boe | C16: 5.8 | D16: 5.8 | E16: 5.8 | F16: 5.8 | G16: 5.8 | H16: S01
A17: Gas & LCE production | B17: mboe/d | C17: 720.86849 | D17: 721.32507 | E17: 751.75882 | F17: 756.67087 | G17: 731.33733 | H17: S02/S05
... A34: Oil total / liquids realisation | B34: x | C34: 0.79217489 | D34: 0.79217489 | E34: 0.79217489 | F34: 0.79217489 | G34: 0.79217489 | H34: S01
A37: WACC BUILD | F37: TERMINAL & EQUITY BRIDGE INPUTS
A38: Input | B38: Unit | C38: Value | D38: Source | F38: Input | G38: Unit | H38: Value
A39: USD risk-free rate | B39: % | C39: 0.0477 | D39: S10 | F39: Perpetual nominal growth | G39: % | H39: 0.015
A40: Equity risk premium | B40: % | C40: 0.0442 | D40: S12 | F40: Terminal incremental ROIC | G40: % | H40: 0.1
A41: Industry unlevered beta | B41: x | C41: 0.63 | D41: S11 | F41: Gross finance debt | G41: $m | H41: 58337
A42: Marginal financing tax shield | B42: % | C42: 0.25 | D42: S19 | F42: Finance debt hedge liability | G42: $m | H42: 1082
A43: Pre-tax cost of debt | B43: % | C43: 0.056831624 | D43: S13 | F43: Net lease liabilities | G43: $m | H43: 13316
A44: Market value of ordinary equity | B44: $m | C44: 114566.62 | D44: S08 | F44: Perpetual hybrid claim | G44: $m | H44: 13015
A45: Debt capital for WACC | B45: $m | C45: 81200 | D45: S02/S19 | F45: Other non-controlling interests | G45: $m | H45: 4977
A46: Relevered beta | B46: x | C46: =C41*(1+(1-C42)*C45/C44) -> 0.96488813 | F46: Pension deficit net of tax | G46: $m | H46: 3099.75
A47: Cost of equity | B47: % | C47: =C39+C46*C40 -> 0.090348056 | F47: Oil-spill claim net of tax asset | G47: $m | H47: 5001
A48: After-tax cost of debt | B48: % | C48: =C43*(1-C42) -> 0.042623718 | F48: Decommissioning claim net of tax | G48: $m | H48: 9189.75
A49: Equity weight | B49: % | C49: =C44/(C44+C45) -> 0.58522039 | F49: Preference share claim | G49: $m | H49: 17.175041
A50: Debt weight | B50: % | C50: =C45/(C44+C45) -> 0.41477961 | F50: Declared dividend per share | G50: USD | H50: 0.0866
A51: WACC | B51: % | C51: =C49*C47+C50*C48 -> 0.070552974 | F51: Cash and equivalents | G51: $m | H51: 37168
F52: Other investments | G52: $m | H52: 762
F53: Expected Castrol proceeds | G53: $m | H53: 6000
F54: Diluted ordinary shares | G54: m | H54: 15849.647
F55: USD per GBP | G55: x | H55: 1.3517
F56: Market price | G56: GBX | H56: 539.7
F57: Valuation date | G57: date | H57: 46269
F58: Ordinary shares excluding treasury | G58: m | H58: 15704.545

Sheet Forecast
A1: BP plc | Operating Forecast & UFCF
A2: 2023A–2025A historicals | 2026E–2030E driver-based forecast | US$ million unless stated
A4: KEY OPERATING DRIVERS
A5: Metric | B5: Unit | C5: 2023A | D5: 2024A | E5: 2025A | F5: 2026E | G5: 2027E | H5: 2028E | I5: 2029E | J5: 2030E
A6: Sales and other operating revenues | B6: $m | C6: 210130 | D6: 189185 | E6: 189335 | F6: =Assumptions!C6 -> 230653.66 | G6: =Assumptions!D6 -> 182932.22 | H6: =Assumptions!E6 -> 178489.94 | I6: =Assumptions!F6 -> 189809.61 | J6: =Assumptions!G6 -> 198410.54
A7: Brent average price | B7: $/bbl | C7: 82.49 | D7: 80.52 | E7: 69.14 | F7: =Assumptions!C7 -> 87 | G7: =Assumptions!D7 -> 69 | H7: =Assumptions!E7 -> 67.324422 | I7: =Assumptions!F7 -> 71.594075 | J7: =Assumptions!G7 -> 74.838251
A8: Oil P&O production | B8: mboe/d | C8: 1383 | D8: 1470 | E8: 1527 | F8: =Assumptions!C9 -> 1504.1315 | G8: =Assumptions!D9 -> 1498.6238 | H8: =Assumptions!E9 -> 1502.7874 | I8: =Assumptions!F9 -> 1543.3783 | J8: =Assumptions!G9 -> 1613.601
A9: Oil total hydrocarbon realisation | B9: $/boe | C9: 58.34 | D9: 53.96 | E9: 49.45 | F9: =F7*Assumptions!C8 -> 60.154333 | G9: =G7*Assumptions!D8 -> 47.708609 | H9: =H7*Assumptions!E8 -> 46.550066 | I9: =I7*Assumptions!F8 -> 49.502228 | J9: =J7*Assumptions!G8 -> 51.745346
A10: Gas & LCE production | B10: mboe/d | C10: 929 | D10: 888 | E10: 785 | F10: =Assumptions!C17 -> 720.86849 | G10: =Assumptions!D17 -> 721.32507 | H10: =Assumptions!E17 -> 751.75882 | I10: =Assumptions!F17 -> 756.67087 | J10: =Assumptions!G17 -> 731.33733
A11: Gas realised gas price | B11: $/mcf | C11: 6.13 | D11: 5.9 | E11: 6.6 | F11: =Assumptions!C13+Assumptions!C14 -> 6.9289867 | G11: =Assumptions!D13+Assumptions!D14 -> 6.7941767 | H11: =Assumptions!E13+Assumptions!E14 -> 7.4371167 | I11: =Assumptions!F13+Assumptions!F14 -> 7.7067367 | J11: =Assumptions!G13+Assumptions!G14 -> 8.5363367
A12: Customers underlying RC PBIT | B12: $m | F12: =Assumptions!C21 -> 4830 | G12: =Assumptions!D21 -> 3555 | H12: =Assumptions!E21 -> 3626.1 | I12: =Assumptions!F21 -> 3698.622 | J12: =Assumptions!G21 -> 3772.5944
A13: Products underlying RC PBIT | B13: $m | F13: =Assumptions!C22 -> 7177 | G13: =Assumptions!D22 -> 4074.814 | H13: =Assumptions!E22 -> 3121.4636 | I13: =Assumptions!F22 -> 3121.4636 | J13: =Assumptions!G22 -> 3121.4636
A15: SEGMENT OPERATING BUILD
A16: Metric | B16: Unit | C16: 2023A | D16: 2024A | E16: 2025A | F16: 2026E | G16: 2027E | H16: 2028E | I16: 2029E | J16: 2030E
A17: Oil production × realisation proxy | B17: $m | C17: 29449.74 | D17: 29031.559 | E17: 27561.205 | F17: =F8*365*F9/1000 -> 33025.21 | G17: =G8*365*G9/1000 -> 26096.498 | H17: =H8*366*H9/1000 -> 25603.475 | I17: =I8*365*I9/1000 -> 27886.242 | J17: =J8*365*J9/1000 -> 30476.164
A18: Oil adjusted EBITDA | B18: $m | C18: 18857 | D18: 19278 | E18: 17446 | F18: =F17*Assumptions!C10 -> 21573.026 | G18: =G17*Assumptions!D10 -> 16936.627 | H18: =H17*Assumptions!E10 -> 16616.656 | I18: =I17*Assumptions!F10 -> 18098.171 | J18: =J17*Assumptions!G10 -> 19779.031
A19: Oil D&A | B19: $m | C19: 5692 | D19: 6797 | E19: 7719 | F19: =F8*365*Assumptions!C11/1000 -> 7678.52 | G19: =G8*365*Assumptions!D11/1000 -> 7657.9675 | H19: =H8*366*Assumptions!E11/1000 -> 7700.2825 | I19: =I8*365*Assumptions!F11/1000 -> 7886.663 | J19: =J8*365*Assumptions!G11/1000 -> 8245.501
A20: Oil exploration write-offs | B20: $m | C20: 384 | D20: 544 | E20: 313 | F20: =Assumptions!C12 -> 660 | G20: =Assumptions!D12 -> 400 | H20: =Assumptions!E12 -> 400 | I20: =Assumptions!F12 -> 400 | J20: =Assumptions!G12 -> 400
A21: Oil P&O underlying RC PBIT | B21: $m | C21: 12781 | D21: 11937 | E21: 9414 | F21: =F18-F19-F20 -> 13234.506 | G21: =G18-G19-G20 -> 8878.66 | H21: =H18-H19-H20 -> 8516.3731 | I21: =I18-I19-I20 -> 9811.5083 | J21: =J18-J19-J20 -> 11133.53
A22: Gas total hydrocarbon realisation | B22: $/boe | C22: 40.21 | D22: 38.57 | E22: 41.34 | F22: =Assumptions!C15*(F9/Assumptions!C34)+(1-Assumptions!C15)*F11*Assumptions!C16 -> 44.120353 | G22: =Assumptions!D15*(G9/Assumptions!D34)+(1-Assumptions!D15)*G11*Assumptions!D16 -> 41.696273 | H22: =Assumptions!E15*(H9/Assumptions!E34)+(1-Assumptions!E15)*H11*Assumptions!E16 -> 44.854256 | I22: =Assumptions!F15*(I9/Assumptions!F34)+(1-Assumptions!F15)*I11*Assumptions!F16 -> 46.655966 | J22: =Assumptions!G15*(J9/Assumptions!G34)+(1-Assumptions!G15)*J11*Assumptions!G16 -> 51.249837
A23: Gas production × realisation proxy | B23: $m | C23: 13634.608 | D23: 12535.559 | E23: 11844.943 | F23: =F10*365*F22/1000 -> 11608.815 | G23: =G10*365*G22/1000 -> 10977.947 | H23: =H10*366*H22/1000 -> 12341.367 | I23: =I10*365*I22/1000 -> 12885.672 | J23: =J10*365*J22/1000 -> 13680.535
A24: Gas adjusted EBITDA | B24: $m | C24: 14764 | D24: 11860 | E24: 10366 | F24: =F23*Assumptions!C18 -> 10286.136 | G24: =G23*Assumptions!D18 -> 9682.5492 | H24: =H23*Assumptions!E18 -> 10885.086 | I24: =I23*Assumptions!F18 -> 11365.163 | J24: =J23*Assumptions!G18 -> 12066.232
A25: Gas D&A | B25: $m | C25: 5680 | D25: 4835 | E25: 4969 | F25: =F10*365*Assumptions!C19/1000 -> 4318.83 | G25: =G10*365*Assumptions!D19/1000 -> 4344.1802 | H25: =H10*366*Assumptions!E19/1000 -> 4539.8715 | I25: =I10*365*Assumptions!F19/1000 -> 4557.0503 | J25: =J10*365*Assumptions!G19/1000 -> 4404.4791
A26: Gas exploration write-offs | B26: $m | C26: 362 | D26: 222 | E26: 30 | F26: =Assumptions!C20 -> 98 | G26: =Assumptions!D20 -> 100 | H26: =Assumptions!E20 -> 100 | I26: =Assumptions!F20 -> 100 | J26: =Assumptions!G20 -> 100
A27: Gas & LCE underlying RC PBIT | B27: $m | C27: 8722 | D27: 6803 | E27: 5367 | F27: =F24-F25-F26 -> 5869.3056 | G27: =G24-G25-G26 -> 5238.3689 | H27: =H24-H25-H26 -> 6245.2143 | I27: =I24-I25-I26 -> 6708.1123 | J27: =J24-J25-J26 -> 7561.7531
A28: Customers & Products underlying RC PBIT | B28: $m | C28: 6413 | D28: 2517 | E28: 5272 | F28: =F12+F13 -> 12007 | G28: =G12+G13 -> 7629.814 | H28: =H12+H13 -> 6747.5636 | I28: =I12+I13 -> 6820.0856 | J28: =J12+J13 -> 6894.058
A29: Other businesses & corporate | B29: $m | C29: -866 | D29: -608 | E29: -648 | F29: =Assumptions!C23 -> -1000 | G29: =Assumptions!D23 -> -900 | H29: =Assumptions!E23 -> -900 | I29: =Assumptions!F23 -> -900 | J29: =Assumptions!G23 -> -900
A30: UPII consolidation adjustment | B30: $m | C30: -14 | D30: -25 | E30: 45 | F30: =Assumptions!C24 -> 21 | G30: =Assumptions!D24 -> 0 | H30: =Assumptions!E24 -> 0 | I30: =Assumptions!F24 -> 0 | J30: =Assumptions!G24 -> 0
A31: Group underlying RC PBIT | B31: $m | C31: 27036 | D31: 20624 | E31: 19450 | F31: =F21+F27+F28+F29+F30 -> 30131.812 | G31: =G21+G27+G28+G29+G30 -> 20846.843 | H31: =H21+H27+H28+H29+H30 -> 20609.151 | I31: =I21+I27+I28+I29+I30 -> 22439.706 | J31: =J21+J27+J28+J29+J30 -> 24689.341
A33: UNLEVERED FREE CASH FLOW
A34: Metric | B34: Unit | C34: 2023A | D34: 2024A | E34: 2025A | F34: 2026E | G34: 2027E | H34: 2028E | I34: 2029E | J34: 2030E
A35: Less: equity-accounted income | B35: $m | C35: 898 | D35: 1993 | E35: 618 | F35: =Assumptions!C25 -> 2500 | G35: =Assumptions!D25 -> 2500 | H35: =Assumptions!E25 -> 2500 | I35: =Assumptions!F25 -> 2500 | J35: =Assumptions!G25 -> 2500
A36: Less: non-operating financing income | B36: $m | C36: 1265 | D36: 1512 | E36: 1352 | F36: =Assumptions!C26 -> 1352 | G36: =Assumptions!D26 -> 1352 | H36: =Assumptions!E26 -> 1352 | I36: =Assumptions!F26 -> 1352 | J36: =Assumptions!G26 -> 1352
A37: Adjusted consolidated EBIT | B37: $m | C37: 24873 | D37: 17119 | E37: 17480 | F37: =F31-F35-F36 -> 26279.812 | G37: =G31-G35-G36 -> 16994.843 | H37: =H31-H35-H36 -> 16757.151 | I37: =I31-I35-I36 -> 18587.706 | J37: =J31-J35-J36 -> 20837.341
A38: Operating tax rate | B38: % | C38: 0.4 | D38: 0.4 | E38: 0.42 | F38: =Assumptions!C27 -> 0.375 | G38: =Assumptions!D27 -> 0.4 | H38: =Assumptions!E27 -> 0.4 | I38: =Assumptions!F27 -> 0.4 | J38: =Assumptions!G27 -> 0.4
A39: Operating cash-tax proxy | B39: $m | C39: 9949.2 | D39: 6847.6 | E39: 7341.6 | F39: =F37*F38 -> 9854.9295 | G39: =G37*G38 -> 6797.9372 | H39: =H37*H38 -> 6702.8604 | I39: =I37*I38 -> 7435.0825 | J39: =J37*J38 -> 8334.9364
A40: NOPAT | B40: $m | C40: 14923.8 | D40: 10271.4 | E40: 10138.4 | F40: =F37-F39 -> 16424.882 | G40: =G37-G39 -> 10196.906 | H40: =H37-H39 -> 10054.291 | I40: =I37-I39 -> 11152.624 | J40: =J37-J39 -> 12502.405
A41: Total consolidated D&A | B41: $m | C41: 15928 | D41: 16622 | E41: 17822 | F41: =F19+F25+Assumptions!C28 -> 16939.35 | G41: =G19+G25+Assumptions!D28 -> 17042.988 | H41: =H19+H25+Assumptions!E28 -> 17381.811 | I41: =I19+I25+Assumptions!F28 -> 17688.203 | J41: =J19+J25+Assumptions!G28 -> 17999.36
A42: Cash capital expenditure | B42: $m | C42: 16253 | D42: 16237 | E42: 14533 | F42: =Assumptions!C29 -> 13750 | G42: =Assumptions!D29 -> 14000 | H42: =Assumptions!E29 -> 14000 | I42: =Assumptions!F29 -> 14000 | J42: =Assumptions!G29 -> 14000
A43: Net lease asset additions | B43: $m | C43: 3000 | D43: 3781 | E43: 4349 | F43: =Assumptions!C30 -> 3100 | G43: =Assumptions!D30 -> 3100 | H43: =Assumptions!E30 -> 3100 | I43: =Assumptions!F30 -> 3100 | J43: =Assumptions!G30 -> 3100
...

Sheet DCF
A1: BP plc | Discounted Cash Flow Valuation
A2: Residual cash flows after 4 September 2026 | mid-year convention | terminal reinvestment normalisation
A4: A. EXPLICIT FORECAST UFCF
A5: Metric | B5: Unit | C5: 2026 stub | D5: 2027E | E5: 2028E | F5: 2029E | G5: 2030E
A6: Full-year UFCF | B6: $m | C6: =Forecast!F48 -> 12657.783 | D6: =Forecast!G48 -> 13884.253 | E6: =Forecast!H48 -> 12589.171 | F6: =Forecast!I48 -> 13450.78 | G6: =Forecast!J48 -> 15205.398
A7: Less: H1 2026 UFCF proxy | B7: $m | C7: =Support!C28 -> 4576.24
A8: H2 2026 UFCF | B8: $m | C8: =C6-C7 -> 8081.5426
A9: Remaining H2 fraction | B9: % | C9: =Support!D36/Support!D35 -> 0.64130435
A10: UFCF after valuation date | B10: $m | C10: =C8*C9 -> 5182.7284 | D10: =D6 -> 13884.253 | E10: =E6 -> 12589.171 | F10: =F6 -> 13450.78 | G10: =G6 -> 15205.398
A11: Cash-flow midpoint | B11: date | C11: =Assumptions!H57+Support!D36/2 -> 46328 | D11: =DATE(2027,7,2) -> 46570 | E11: =DATE(2028,7,1)+0.5 -> 46935.5 | F11: =DATE(2029,7,2) -> 47301 | G11: =DATE(2030,7,2) -> 47666
A12: Years from valuation | B12: years | C12: =(C11-Assumptions!H57)/365.25 -> 0.1615332 | D12: =(D11-Assumptions!H57)/365.25 -> 0.82409309 | E12: =(E11-Assumptions!H57)/365.25 -> 1.8247775 | F12: =(F11-Assumptions!H57)/365.25 -> 2.825462 | G12: =(G11-Assumptions!H57)/365.25 -> 3.8247775
A13: Discount factor | B13: x | C13: =1/(1+Assumptions!C51)^C12 -> 0.98904784 | D13: =1/(1+Assumptions!C51)^D12 -> 0.9453663 | E13: =1/(1+Assumptions!C51)^E12 -> 0.88302234 | F13: =1/(1+Assumptions!C51)^F12 -> 0.82478976 | G13: =1/(1+Assumptions!C51)^G12 -> 0.77046935
A14: Present value of UFCF | B14: $m | C14: =C10*C13 -> 5125.9664 | D14: =D10*D13 -> 13125.704 | E14: =E10*E13 -> 11116.519 | F14: =F10*F13 -> 11094.066 | G14: =G10*G13 -> 11715.293
A16: B. TERMINAL VALUE
A17: Terminal growth | B17: % | C17: =Assumptions!H39 -> 0.015
A18: WACC | B18: % | C18: =Assumptions!C51 -> 0.070552974
A19: 2031 NOPAT | B19: $m | C19: =Forecast!J40*(1+C17) -> 12689.941
A20: 2031 D&A | B20: $m | C20: =Forecast!J41*(1+C17) -> 18269.35
A21: 2031 cash + lease capex floor | B21: $m | C21: =(Forecast!J42+Forecast!J43)*(1+C17) -> 17356.5
A22: Growth reinvestment requirement | B22: $m | C22: =C19*C17/Assumptions!H40 -> 1903.4911
A23: Terminal capex incl. lease additions | B23: $m | C23: =MAX(C21,C20+C22) -> 20172.841
A24: 2031 change in working capital | B24: $m | C24: =Forecast!J6*C17*Assumptions!G31 -> 102.5508
A25: 2031 JV cash dividends | B25: $m | C25: =Forecast!J45*(1+C17) -> 2131.5
A26: 2031 exploration write-offs | B26: $m | C26: =Forecast!J46*(1+C17) -> 507.5
A27: 2031 cash restructuring | B27: $m | C27: =Forecast!J47*(1+C17) -> 507.5
A28: Normalised 2031 UFCF | B28: $m | C28: =C19+C20-C23-C24+C25+C26-C27 -> 12815.399
A29: Terminal value at 31 Dec 2030 | B29: $m | C29: =C28/(C18-C17) -> 230687.9
A30: Terminal discount period | B30: years | C30: =(DATE(2030,12,31)-Assumptions!H57)/365.25 -> 4.3230664
A31: PV of terminal value | B31: $m | C31: =C29/(1+C18)^C30 -> 171801.43
A32: PV of explicit-period UFCF | B32: $m | C32: =SUM(C14:G14) -> 52177.549
A33: Operating enterprise value | B33: $m | C33: =C31+C32 -> 223978.97
A34: PV terminal value / enterprise value | B34: % | C34: =C31/C33 -> 0.76704265
A36: C. ENTERPRISE VALUE → EQUITY VALUE
A37: Gross finance debt | B37: $m | C37: =-Assumptions!H41 -> -58337
A38: Finance debt hedge liability | B38: $m | C38: =-Assumptions!H42 -> -1082
A39: Net lease liabilities | B39: $m | C39: =-Assumptions!H43 -> -13316
A40: Perpetual hybrid claim | B40: $m | C40: =-Assumptions!H44 -> -13015
A41: Other non-controlling interests | B41: $m | C41: =-Assumptions!H45 -> -4977
A42: Pension deficit net of tax | B42: $m | C42: =-Assumptions!H46 -> -3099.75
A43: Oil-spill claim net of tax asset | B43: $m | C43: =-Assumptions!H47 -> -5001
...

Sheet Sensitivity
A1: BP plc | Sensitivity & Operating Scenarios
A2: WACC / terminal growth sensitivity separated from Bear / Base / Bull operating cases
A4: DCF SENSITIVITY: WACC × PERPETUAL GROWTH | J4: OPERATING SCENARIOS
A5: WACC / g | B5: 0 | C5: 0.005 | D5: 0.01 | E5: 0.015 | F5: 0.02 | G5: 0.025 | H5: 0.03 | J5: Driver | K5: Unit | L5: Bear | M5: Base | N5: Bull
A6: 0.055552974 | B6: =((DCF!C10/(1+$A6)^DCF!C12+DCF!D10/(1+$A6)^DCF!D12+DCF!E10/(1+$A6)^DCF!E12+DCF!F10/(1+$A6)^DCF!F12+DCF!G10/(1+$A6)^DCF!G12)+((((Forecast!J40*(1+B$5))+(Forecast!J41*(1+B$5))-MAX(((Forecast!J42+Forecast!J43)*(1+B$5)),(Forecast!J41*(1+B$5))+((Forecast!J40*(1+B$5))*B$5/Assumptions!H40))-(Forecast!J6*B$5*Assumptions!G31)+(Forecast!J45*(1+B$5))+(Forecast!J46*(1+B$5))-(Forecast!J47*(1+B$5)))/($A6-B$5))/(1+$A6)^DCF!C30)+(DCF!C50-DCF!C49)+(Assumptions!H53/(1+$A6)^((DATE(2026,12,31)-Assumptions!H57)/365.25)))/Assumptions!H54/Assumptions!H55*100 -> 915.9644 | C6: =((DCF!C10/(1+$A6)^DCF!C12+DCF!D10/(1+$A6)^DCF!D12+DCF!E10/(1+$A6)^DCF!E12+DCF!F10/(1+$A6)^DCF!F12+DCF!G10/(1+$A6)^DCF!G12)+((((Forecast!J40*(1+C$5))+(Forecast!J41*(1+C$5))-MAX(((Forecast!J42+Forecast!J43)*(1+C$5)),(Forecast!J41*(1+C$5))+((Forecast!J40*(1+C$5))*C$5/Assumptions!H40))-(Forecast!J6*C$5*Assumptions!G31)+(Forecast!J45*(1+C$5))+(Forecast!J46*(1+C$5))-(Forecast!J47*(1+C$5)))/($A6-C$5))/(1+$A6)^DCF!C30)+(DCF!C50-DCF!C49)+(Assumptions!H53/(1+$A6)^((DATE(2026,12,31)-Assumptions!H57)/365.25)))/Assumptions!H54/Assumptions!H55*100 -> 968.94317 | D6: =((DCF!C10/(1+$A6)^DCF!C12+DCF!D10/(1+$A6)^DCF!D12+DCF!E10/(1+$A6)^DCF!E12+DCF!F10/(1+$A6)^DCF!F12+DCF!G10/(1+$A6)^DCF!G12)+((((Forecast!J40*(1+D$5))+(Forecast!J41*(1+D$5))-MAX(((Forecast!J42+Forecast!J43)*(1+D$5)),(Forecast!J41*(1+D$5))+((Forecast!J40*(1+D$5))*D$5/Assumptions!H40))-(Forecast!J6*D$5*Assumptions!G31)+(Forecast!J45*(1+D$5))+(Forecast!J46*(1+D$5))-(Forecast!J47*(1+D$5)))/($A6-D$5))/(1+$A6)^DCF!C30)+(DCF!C50-DCF!C49)+(Assumptions!H53/(1+$A6)^((DATE(2026,12,31)-Assumptions!H57)/365.25)))/Assumptions!H54/Assumptions!H55*100 -> 1033.045 | E6: =((DCF!C10/(1+$A6)^DCF!C12+DCF!D10/(1+$A6)^DCF!D12+DCF!E10/(1+$A6)^DCF!E12+DCF!F10/(1+$A6)^DCF!F12+DCF!G10/(1+$A6)^DCF!G12)+((((Forecast!J40*(1+E$5))+(Forecast!J41*(1+E$5))-MAX(((Forecast!J42+Forecast!J43)*(1+E$5)),(Forecast!J41*(1+E$5))+((Forecast!J40*(1+E$5))*E$5/Assumptions!H40))-(Forecast!J6*E$5*Assumptions!G31)+(Forecast!J45*(1+E$5))+(Forecast!J46*(1+E$5))-(Forecast!J47*(1+E$5)))/($A6-E$5))/(1+$A6)^DCF!C30)+(DCF!C50-DCF!C49)+(Assumptions!H53/(1+$A6)^((DATE(2026,12,31)-Assumptions!H57)/365.25)))/Assumptions!H54/Assumptions!H55*100 -> 1112.3843 | F6: =((DCF!C10/(1+$A6)^DCF!C12+DCF!D10/(1+$A6)^DCF!D12+DCF!E10/(1+$A6)^DCF!E12+DCF!F10/(1+$A6)^DCF!F12+DCF!G10/(1+$A6)^DCF!G12)+((((Forecast!J40*(1+F$5))+(Forecast!J41*(1+F$5))-MAX(((Forecast!J42+Forecast!J43)*(1+F$5)),(Forecast!J41*(1+F$5))+((Forecast!J40*(1+F$5))*F$5/Assumptions!H40))-(Forecast!J6*F$5*Assumptions!G31)+(Forecast!J45*(1+F$5))+(Forecast!J46*(1+F$5))-(Forecast!J47*(1+F$5)))/($A6-F$5))/(1+$A6)^DCF!C30)+(DCF!C50-DCF!C49)+(Assumptions!H53/(1+$A6)^((DATE(2026,12,31)-Assumptions!H57)/365.25)))/Assumptions!H54/Assumptions!H55*100 -> 1213.3897 | G6: =((DCF!C10/(1+$A6)^DCF!C12+DCF!D10/(1+$A6)^DCF!D12+DCF!E10/(1+$A6)^DCF!E12+DCF!F10/(1+$A6)^DCF!F12+DCF!G10/(1+$A6)^DCF!G12)+((((Forecast!J40*(1+G$5))+(Forecast!J41*(1+G$5))-MAX(((Forecast!J42+Forecast!J43)*(1+G$5)),(Forecast!J41*(1+G$5))+((Forecast!J40*(1+G$5))*G$5/Assumptions!H40))-(Forecast!J6*G$5*Assumptions!G31)+(Forecast!J45*(1+G$5))+(Forecast!J46*(1+G$5))-(Forecast!J47*(1+G$5)))/($A6-G$5))/(1+$A6)^DCF!C30)+(DCF!C50-DCF!C49)+(Assumptions!H53/(1+$A6)^((DATE(2026,12,31)-Assumptions!H57)/365.25)))/Assumptions!H54/Assumptions!H55*100 -> 1346.6982 | H6: =((DCF!C10/(1+$A6)^DCF!C12+DCF!D10/(1+$A6)^DCF!D12+DCF!E10/(1+$A6)^DCF!E12+DCF!F10/(1+$A6)^DCF!F12+DCF!G10/(1+$A6)^DCF!G12)+((((Forecast!J40*(1+H$5))+(Forecast!J41*(1+H$5))-MAX(((Forecast!J42+Forecast!J43)*(1+H$5)),(Forecast!J41*(1+H$5))+((Forecast!J40*(1+H$5))*H$5/Assumptions!H40))-(Forecast!J6*H$5*Assumptions!G31)+(Forecast!J45*(1+H$5))+(Forecast!J46*(1+H$5))-(Forecast!J47*(1+H$5)))/($A6-H$5))/(1+$A6)^DCF!C30)+(DCF!C50-DCF!C49)+(Assumptions!H53/(1+$A6)^((DATE(2026,12,31)-Assumptions!H57)/365.25)))/Assumptions!H54/Assumptions!H55*100 -> 1531.2724 | J6: Brent / oil realisation | K6: % vs Base | L6: -0.1 | M6: 0 | N6: 0.1
A7: 0.060552974 | B7: =((DCF!C10/(1+$A7)^DCF!C12+DCF!D10/(1+$A7)^DCF!D12+DCF!E10/(1+$A7)^DCF!E12+DCF!F10/(1+$A7)^DCF!F12+DCF!G10/(1+$A7)^DCF!G12)+((((Forecast!J40*(1+B$5))+(Forecast!J41*(1+B$5))-MAX(((Forecast!J42+Forecast!J43)*(1+B$5)),(Forecast!J41*(1+B$5))+((Forecast!J40*(1+B$5))*B$5/Assumptions!H40))-(Forecast!J6*B$5*Assumptions!G31)+(Forecast!J45*(1+B$5))+(Forecast!J46*(1+B$5))-(Forecast!J47*(1+B$5)))/($A7-B$5))/(1+$A7)^DCF!C30)+(DCF!C50-DCF!C49)+(Assumptions!H53/(1+$A7)^((DATE(2026,12,31)-Assumptions!H57)/365.25)))/Assumptions!H54/Assumptions!H55*100 -> 815.24459 | C7: =((DCF!C10/(1+$A7)^DCF!C12+DCF!D10/(1+$A7)^DCF!D12+DCF!E10/(1+$A7)^DCF!E12+DCF!F10/(1+$A7)^DCF!F12+DCF!G10/(1+$A7)^DCF!G12)+((((Forecast!J40*(1+C$5))+(Forecast!J41*(1+C$5))-MAX(((Forecast!J42+Forecast!J43)*(1+C$5)),(Forecast!J41*(1+C$5))+((Forecast!J40*(1+C$5))*C$5/Assumptions!H40))-(Forecast!J6*C$5*Assumptions!G31)+(Forecast!J45*(1+C$5))+(Forecast!J46*(1+C$5))-(Forecast!J47*(1+C$5)))/($A7-C$5))/(1+$A7)^DCF!C30)+(DCF!C50-DCF!C49)+(Assumptions!H53/(1+$A7)^((DATE(2026,12,31)-Assumptions!H57)/365.25)))/Assumptions!H54/Assumptions!H55*100 -> 855.40823 | D7: =((DCF!C10/(1+$A7)^DCF!C12+DCF!D10/(1+$A7)^DCF!D12+DCF!E10/(1+$A7)^DCF!E12+DCF!F10/(1+$A7)^DCF!F12+DCF!G10/(1+$A7)^DCF!G12)+((((Forecast!J40*(1+D$5))+(Forecast!J41*(1+D$5))-MAX(((Forecast!J42+Forecast!J43)*(1+D$5)),(Forecast!J41*(1+D$5))+((Forecast!J40*(1+D$5))*D$5/Assumptions!H40))-(Forecast!J6*D$5*Assumptions!G31)+(Forecast!J45*(1+D$5))+(Forecast!J46*(1+D$5))-(Forecast!J47*(1+D$5)))/($A7-D$5))/(1+$A7)^DCF!C30)+(DCF!C50-DCF!C49)+(Assumptions!H53/(1+$A7)^((DATE(2026,12,31)-Assumptions!H57)/365.25)))/Assumptions!H54/Assumptions!H55*100 -> 903.06907 | E7: =((DCF!C10/(1+$A7)^DCF!C12+DCF!D10/(1+$A7)^DCF!D12+DCF!E10/(1+$A7)^DCF!E12+DCF!F10/(1+$A7)^DCF!F12+DCF!G10/(1+$A7)^DCF!G12)+((((Forecast!J40*(1+E$5))+(Forecast!J41*(1+E$5))-MAX(((Forecast!J42+Forecast!J43)*(1+E$5)),(Forecast!J41*(1+E$5))+((Forecast!J40*(1+E$5))*E$5/Assumptions!H40))-(Forecast!J6*E$5*Assumptions!G31)+(Forecast!J45*(1+E$5))+(Forecast!J46*(1+E$5))-(Forecast!J47*(1+E$5)))/($A7-E$5))/(1+$A7)^DCF!C30)+(DCF!C50-DCF!C49)+(Assumptions!H53/(1+$A7)^((DATE(2026,12,31)-Assumptions!H57)/365.25)))/Assumptions!H54/Assumptions!H55*100 -> 960.69586 | F7: =((DCF!C10/(1+$A7)^DCF!C12+DCF!D10/(1+$A7)^DCF!D12+DCF!E10/(1+$A7)^DCF!E12+DCF!F10/(1+$A7)^DCF!F12+DCF!G10/(1+$A7)^DCF!G12)+((((Forecast!J40*(1+F$5))+(Forecast!J41*(1+F$5))-MAX(((Forecast!J42+Forecast!J43)*(1+F$5)),(Forecast!J41*(1+F$5))+((Forecast!J40*(1+F$5))*F$5/Assumptions!H40))-(Forecast!J6*F$5*Assumptions!G31)+(Forecast!J45*(1+F$5))+(Forecast!J46*(1+F$5))-(Forecast!J47*(1+F$5)))/($A7-F$5))/(1+$A7)^DCF!C30)+(DCF!C50-DCF!C49)+(Assumptions!H53/(1+$A7)^((DATE(2026,12,31)-Assumptions!H57)/365.25)))/Assumptions!H54/Assumptions!H55*100 -> 1031.9749 | G7: =((DCF!C10/(1+$A7)^DCF!C12+DCF!D10/(1+$A7)^DCF!D12+DCF!E10/(1+$A7)^DCF!E12+DCF!F10/(1+$A7)^DCF!F12+DCF!G10/(1+$A7)^DCF!G12)+((((Forecast!J40*(1+G$5))+(Forecast!J41*(1+G$5))-MAX(((Forecast!J42+Forecast!J43)*(1+G$5)),(Forecast!J41*(1+G$5))+((Forecast!J40*(1+G$5))*G$5/Assumptions!H40))-(Forecast!J6*G$5*Assumptions!G31)+(Forecast!J45*(1+G$5))+(Forecast!J46*(1+G$5))-(Forecast!J47*(1+G$5)))/($A7-G$5))/(1+$A7)^DCF!C30)+(DCF!C50-DCF!C49)+(Assumptions!H53/(1+$A7)^((DATE(2026,12,31)-Assumptions!H57)/365.25)))/Assumptions!H54/Assumptions!H55*100 -> 1122.666 | H7: =((DCF!C10/(1+$A7)^DCF!C12+DCF!D10/(1+$A7)^DCF!D12+DCF!E10/(1+$A7)^DCF!E12+DCF!F10/(1+$A7)^DCF!F12+DCF!G10/(1+$A7)^DCF!G12)+((((Forecast!J40*(1+H$5))+(Forecast!J41*(1+H$5))-MAX(((Forecast!J42+Forecast!J43)*(1+H$5)),(Forecast!J41*(1+H$5))+((Forecast!J40*(1+H$5))*H$5/Assumptions!H40))-(Forecast!J6*H$5*Assumptions!G31)+(Forecast!J45*(1+H$5))+(Forecast!J46*(1+H$5))-(Forecast!J47*(1+H$5)))/($A7-H$5))/(1+$A7)^DCF!C30)+(DCF!C50-DCF!C49)+(Assumptions!H53/(1+$A7)^((DATE(2026,12,31)-Assumptions!H57)/365.25)))/Assumptions!H54/Assumptions!H55*100 -> 1242.2998 | J7: Upstream production | K7: % vs Base | L7: -0.03 | M7: 0 | N7: 0.03
A8: 0.065552974 | B8: =((DCF!C10/(1+$A8)^DCF!C12+DCF!D10/(1+$A8)^DCF!D12+DCF!E10/(1+$A8)^DCF!E12+DCF!F10/(1+$A8)^DCF!F12+DCF!G10/(1+$A8)^DCF!G12)+((((Forecast!J40*(1+B$5))+(Forecast!J41*(1+B$5))-MAX(((Forecast!J42+Forecast!J43)*(1+B$5)),(Forecast!J41*(1+B$5))+((Forecast!J40*(1+B$5))*B$5/Assumptions!H40))-(Forecast!J6*B$5*Assumptions!G31)+(Forecast!J45*(1+B$5))+(Forecast!J46*(1+B$5))-(Forecast!J47*(1+B$5)))/($A8-B$5))/(1+$A8)^DCF!C30)+(DCF!C50-DCF!C49)+(Assumptions!H53/(1+$A8)^((DATE(2026,12,31)-Assumptions!H57)/365.25)))/Assumptions!H54/Assumptions!H55*100 -> 729.96399 | C8: =((DCF!C10/(1+$A8)^DCF!C12+DCF!D10/(1+$A8)^DCF!D12+DCF!E10/(1+$A8)^DCF!E12+DCF!F10/(1+$A8)^DCF!F12+DCF!G10/(1+$A8)^DCF!G12)+((((Forecast!J40*(1+C$5))+(Forecast!J41*(1+C$5))-MAX(((Forecast!J42+Forecast!J43)*(1+C$5)),(Forecast!J41*(1+C$5))+((Forecast!J40*(1+C$5))*C$5/Assumptions!H40))-(Forecast!J6*C$5*Assumptions!G31)+(Forecast!J45*(1+C$5))+(Forecast!J46*(1+C$5))-(Forecast!J47*(1+C$5)))/($A8-C$5))/(1+$A8)^DCF!C30)+(DCF!C50-DCF!C49)+(Assumptions!H53/(1+$A8)^((DATE(2026,12,31)-Assumptions!H57)/365.25)))/Assumptions!H54/Assumptions!H55*100 -> 760.68199 | D8: =((DCF!C10/(1+$A8)^DCF!C12+DCF!D10/(1+$A8)^DCF!D12+DCF!E10/(1+$A8)^DCF!E12+DCF!F10/(1+$A8)^DCF!F12+DCF!G10/(1+$A8)^DCF!G12)+((((Forecast!J40*(1+D$5))+(Forecast!J41*(1+D$5))-MAX(((Forecast!J42+Forecast!J43)*(1+D$5)),(Forecast!J41*(1+D$5))+((Forecast!J40*(1+D$5))*D$5/Assumptions!H40))-(Forecast!J6*D$5*Assumptions!G31)+(Forecast!J45*(1+D$5))+(Forecast!J46*(1+D$5))-(Forecast!J47*(1+D$5)))/($A8-D$5))/(1+$A8)^DCF!C30)+(DCF!C50-DCF!C49)+(Assumptions!H53/(1+$A8)^((DATE(2026,12,31)-Assumptions!H57)/365.25)))/Assumptions!H54/Assumptions!H55*100 -> 796.53034 | E8: =((DCF!C10/(1+$A8)^DCF!C12+DCF!D10/(1+$A8)^DCF!D12+DCF!E10/(1+$A8)^DCF!E12+DCF!F10/(1+$A8)^DCF!F12+DCF!G10/(1+$A8)^DCF!G12)+((((Forecast!J40*(1+E$5))+(Forecast!J41*(1+E$5))-MAX(((Forecast!J42+Forecast!J43)*(1+E$5)),(Forecast!J41*(1+E$5))+((Forecast!J40*(1+E$5))*E$5/Assumptions!H40))-(Forecast!J6*E$5*Assumptions!G31)+(Forecast!J45*(1+E$5))+(Forecast!J46*(1+E$5))-(Forecast!J47*(1+E$5)))/($A8-E$5))/(1+$A8)^DCF!C30)+(DCF!C50-DCF!C49)+(Assumptions!H53/(1+$A8)^((DATE(2026,12,31)-Assumptions!H57)/365.25)))/Assumptions!H54/Assumptions!H55*100 -> 839.03129 | F8: =((DCF!C10/(1+$A8)^DCF!C12+DCF!D10/(1+$A8)^DCF!D12+DCF!E10/(1+$A8)^DCF!E12+DCF!F10/(1+$A8)^DCF!F12+DCF!G10/(1+$A8)^DCF!G12)+((((Forecast!J40*(1+F$5))+(Forecast!J41*(1+F$5))-MAX(((Forecast!J42+Forecast!J43)*(1+F$5)),(Forecast!J41*(1+F$5))+((Forecast!J40*(1+F$5))*F$5/Assumptions!H40))-(Forecast!J6*F$5*Assumptions!G31)+(Forecast!J45*(1+F$5))+(Forecast!J46*(1+F$5))-(Forecast!J47*(1+F$5)))/($A8-F$5))/(1+$A8)^DCF!C30)+(DCF!C50-DCF!C49)+(Assumptions!H53/(1+$A8)^((DATE(2026,12,31)-Assumptions!H57)/365.25)))/Assumptions!H54/Assumptions!H55*100 -> 890.37545 | G8: =((DCF!C10/(1+$A8)^DCF!C12+DCF!D10/(1+$A8)^DCF!D12+DCF!E10/(1+$A8)^DCF!E12+DCF!F10/(1+$A8)^DCF!F12+DCF!G10/(1+$A8)^DCF!G12)+((((Forecast!J40*(1+G$5))+(Forecast!J41*(1+G$5))-MAX(((Forecast!J42+Forecast!J43)*(1+G$5)),(Forecast!J41*(1+G$5))+((Forecast!J40*(1+G$5))*G$5/Assumptions!H40))-(Forecast!J6*G$5*Assumptions!G31)+(Forecast!J45*(1+G$5))+(Forecast!J46*(1+G$5))-(Forecast!J47*(1+G$5)))/($A8-G$5))/(1+$A8)^DCF!C30)+(DCF!C50-DCF!C49)+(Assumptions!H53/(1+$A8)^((DATE(2026,12,31)-Assumptions!H57)/365.25)))/Assumptions!H54/Assumptions!H55*100 -> 953.83383 | H8: =((DCF!C10/(1+$A8)^DCF!C12+DCF!D10/(1+$A8)^DCF!D12+DCF!E10/(1+$A8)^DCF!E12+DCF!F10/(1+$A8)^DCF!F12+DCF!G10/(1+$A8)^DCF!G12)+((((Forecast!J40*(1+H$5))+(Forecast!J41*(1+H$5))-MAX(((Forecast!J42+Forecast!J43)*(1+H$5)),(Forecast!J41*(1+H$5))+((Forecast!J40*(1+H$5))*H$5/Assumptions!H40))-(Forecast!J6*H$5*Assumptions!G31)+(Forecast!J45*(1+H$5))+(Forecast!J46*(1+H$5))-(Forecast!J47*(1+H$5)))/($A8-H$5))/(1+$A8)^DCF!C30)+(DCF!C50-DCF!C49)+(Assumptions!H53/(1+$A8)^((DATE(2026,12,31)-Assumptions!H57)/365.25)))/Assumptions!H54/Assumptions!H55*100 -> 1034.5175 | J8: Gas price / G&LCE earnings | K8: % vs Base | L8: -0.1 | M8: 0 | N8: 0.1
A9: 0.070552974 | B9: =((DCF!C10/(1+$A9)^DCF!C12+DCF!D10/(1+$A9)^DCF!D12+DCF!E10/(1+$A9)^DCF!E12+DCF!F10/(1+$A9)^DCF!F12+DCF!G10/(1+$A9)^DCF!G12)+((((Forecast!J40*(1+B$5))+(Forecast!J41*(1+B$5))-MAX(((Forecast!J42+Forecast!J43)*(1+B$5)),(Forecast!J41*(1+B$5))+((Forecast!J40*(1+B$5))*B$5/Assumptions!H40))-(Forecast!J6*B$5*Assumptions!G31)+(Forecast!J45*(1+B$5))+(Forecast!J46*(1+B$5))-(Forecast!J47*(1+B$5)))/($A9-B$5))/(1+$A9)^DCF!C30)+(DCF!C50-DCF!C49)+(Assumptions!H53/(1+$A9)^((DATE(2026,12,31)-Assumptions!H57)/365.25)))/Assumptions!H54/Assumptions!H55*100 -> 656.8373 | C9: =((DCF!C10/(1+$A9)^DCF!C12+DCF!D10/(1+$A9)^DCF!D12+DCF!E10/(1+$A9)^DCF!E12+DCF!F10/(1+$A9)^DCF!F12+DCF!G10/(1+$A9)^DCF!G12)+((((Forecast!J40*(1+C$5))+(Forecast!J41*(1+C$5))-MAX(((Forecast!J42+Forecast!J43)*(1+C$5)),(Forecast!J41*(1+C$5))+((Forecast!J40*(1+C$5))*C$5/Assumptions!H40))-(Forecast!J6*C$5*Assumptions!G31)+(Forecast!J45*(1+C$5))+(Forecast!J46*(1+C$5))-(Forecast!J47*(1+C$5)))/($A9-C$5))/(1+$A9)^DCF!C30)+(DCF!C50-DCF!C49)+(Assumptions!H53/(1+$A9)^((DATE(2026,12,31)-Assumptions!H57)/365.25)))/Assumptions!H54/Assumptions!H55*100 -> 680.45815 | D9: =((DCF!C10/(1+$A9)^DCF!C12+DCF!D10/(1+$A9)^DCF!D12+DCF!E10/(1+$A9)^DCF!E12+DCF!F10/(1+$A9)^DCF!F12+DCF!G10/(1+$A9)^DCF!G12)+((((Forecast!J40*(1+D$5))+(Forecast!J41*(1+D$5))-MAX(((Forecast!J42+Forecast!J43)*(1+D$5)),(Forecast!J41*(1+D$5))+((Forecast!J40*(1+D$5))*D$5/Assumptions!H40))-(Forecast!J6*D$5*Assumptions!G31)+(Forecast!J45*(1+D$5))+(Forecast!J46*(1+D$5))-(Forecast!J47*(1+D$5)))/($A9-D$5))/(1+$A9)^DCF!C30)+(DCF!C50-DCF!C49)+(Assumptions!H53/(1+$A9)^((DATE(2026,12,31)-Assumptions!H57)/365.25)))/Assumptions!H54/Assumptions!H55*100 -> 707.62099 | E9: =((DCF!C10/(1+$A9)^DCF!C12+DCF!D10/(1+$A9)^DCF!D12+DCF!E10/(1+$A9)^DCF!E12+DCF!F10/(1+$A9)^DCF!F12+DCF!G10/(1+$A9)^DCF!G12)+((((Forecast!J40*(1+E$5))+(Forecast!J41*(1+E$5))-MAX(((Forecast!J42+Forecast!J43)*(1+E$5)),(Forecast!J41*(1+E$5))+((Forecast!J40*(1+E$5))*E$5/Assumptions!H40))-(Forecast!J6*E$5*Assumptions!G31)+(Forecast!J45*(1+E$5))+(Forecast!J46*(1+E$5))-(Forecast!J47*(1+E$5)))/($A9-E$5))/(1+$A9)^DCF!C30)+(DCF!C50-DCF!C49)+(Assumptions!H53/(1+$A9)^((DATE(2026,12,31)-Assumptions!H57)/365.25)))/Assumptions!H54/Assumptions!H55*100 -> 739.28221 | F9: =((DCF!C10/(1+$A9)^DCF!C12+DCF!D10/(1+$A9)^DCF!D12+DCF!E10/(1+$A9)^DCF!E12+DCF!F10/(1+$A9)^DCF!F12+DCF!G10/(1+$A9)^DCF!G12)+((((Forecast!J40*(1+F$5))+(Forecast!J41*(1+F$5))-MAX(((Forecast!J42+Forecast!J43)*(1+F$5)),(Forecast!J41*(1+F$5))+((Forecast!J40*(1+F$5))*F$5/Assumptions!H40))-(Forecast!J6*F$5*Assumptions!G31)+(Forecast!J45*(1+F$5))+(Forecast!J46*(1+F$5))-(Forecast!J47*(1+F$5)))/($A9-F$5))/(1+$A9)^DCF!C30)+(DCF!C50-DCF!C49)+(Assumptions!H53/(1+$A9)^((DATE(2026,12,31)-Assumptions!H57)/365.25)))/Assumptions!H54/Assumptions!H55*100 -> 776.77655 | G9: =((DCF!C10/(1+$A9)^DCF!C12+DCF!D10/(1+$A9)^DCF!D12+DCF!E10/(1+$A9)^DCF!E12+DCF!F10/(1+$A9)^DCF!F12+DCF!G10/(1+$A9)^DCF!G12)+((((Forecast!J40*(1+G$5))+(Forecast!J41*(1+G$5))-MAX(((Forecast!J42+Forecast!J43)*(1+G$5)),(Forecast!J41*(1+G$5))+((Forecast!J40*(1+G$5))*G$5/Assumptions!H40))-(Forecast!J6*G$5*Assumptions!G31)+(Forecast!J45*(1+G$5))+(Forecast!J46*(1+G$5))-(Forecast!J47*(1+G$5)))/($A9-G$5))/(1+$A9)^DCF!C30)+(DCF!C50-DCF!C49)+(Assumptions!H53/(1+$A9)^((DATE(2026,12,31)-Assumptions!H57)/365.25)))/Assumptions!H54/Assumptions!H55*100 -> 822.02479 | H9: =((DCF!C10/(1+$A9)^DCF!C12+DCF!D10/(1+$A9)^DCF!D12+DCF!E10/(1+$A9)^DCF!E12+DCF!F10/(1+$A9)^DCF!F12+DCF!G10/(1+$A9)^DCF!G12)+((((Forecast!J40*(1+H$5))+(Forecast!J41*(1+H$5))-MAX(((Forecast!J42+Forecast!J43)*(1+H$5)),(Forecast!J41*(1+H$5))+((Forecast!J40*(1+H$5))*H$5/Assumptions!H40))-(Forecast!J6*H$5*Assumptions!G31)+(Forecast!J45*(1+H$5))+(Forecast!J46*(1+H$5))-(Forecast!J47*(1+H$5)))/($A9-H$5))/(1+$A9)^DCF!C30)+(DCF!C50-DCF!C49)+(Assumptions!H53/(1+$A9)^((DATE(2026,12,31)-Assumptions!H57)/365.25)))/Assumptions!H54/Assumptions!H55*100 -> 877.89499 | J9: Customers & Products profitability | K9: % vs Base | L9: -0.15 | M9: 0 | N9: 0.1
A10: 0.075552974 | B10: =((DCF!C10/(1+$A10)^DCF!C12+DCF!D10/(1+$A10)^DCF!D12+DCF!E10/(1+$A10)^DCF!E12+DCF!F10/(1+$A10)^DCF!F12+DCF!G10/(1+$A10)^DCF!G12)+((((Forecast!J40*(1+B$5))+(Forecast!J41*(1+B$5))-MAX(((Forecast!J42+Forecast!J43)*(1+B$5)),(Forecast!J41*(1+B$5))+((Forecast!J40*(1+B$5))*B$5/Assumptions!H40))-(Forecast!J6*B$5*Assumptions!G31)+(Forecast!J45*(1+B$5))+(Forecast!J46*(1+B$5))-(Forecast!J47*(1+B$5)))/($A10-B$5))/(1+$A10)^DCF!C30)+(DCF!C50-DCF!C49)+(Assumptions!H53/(1+$A10)^((DATE(2026,12,31)-Assumptions!H57)/365.25)))/Assumptions!H54/Assumptions!H55*100 -> 593.44901 | C10: =((DCF!C10/(1+$A10)^DCF!C12+DCF!D10/(1+$A10)^DCF!D12+DCF!E10/(1+$A10)^DCF!E12+DCF!F10/(1+$A10)^DCF!F12+DCF!G10/(1+$A10)^DCF!G12)+((((Forecast!J40*(1+C$5))+(Forecast!J41*(1+C$5))-MAX(((Forecast!J42+Forecast!J43)*(1+C$5)),(Forecast!J41*(1+C$5))+((Forecast!J40*(1+C$5))*C$5/Assumptions!H40))-(Forecast!J6*C$5*Assumptions!G31)+(Forecast!J45*(1+C$5))+(Forecast!J46*(1+C$5))-(Forecast!J47*(1+C$5)))/($A10-C$5))/(1+$A10)^DCF!C30)+(DCF!C50-DCF!C49)+(Assumptions!H53/(1+$A10)^((DATE(2026,12,31)-Assumptions!H57)/365.25)))/Assumptions!H54/Assumptions!H55*100 -> 611.65119 | D10: =((DCF!C10/(1+$A10)^DCF!C12+DCF!D10/(1+$A10)^DCF!D12+DCF!E10/(1+$A10)^DCF!E12+DCF!F10/(1+$A10)^DCF!F12+DCF!G10/(1+$A10)^DCF!G12)+((((Forecast!J40*(1+D$5))+(Forecast!J41*(1+D$5))-MAX(((Forecast!J42+Forecast!J43)*(1+D$5)),(Forecast!J41*(1+D$5))+((Forecast!J40*(1+D$5))*D$5/Assumptions!H40))-(Forecast!J6*D$5*Assumptions!G31)+(Forecast!J45*(1+D$5))+(Forecast!J46*(1+D$5))-(Forecast!J47*(1+D$5)))/($A10-D$5))/(1+$A10)^DCF!C30)+(DCF!C50-DCF!C49)+(Assumptions!H53/(1+$A10)^((DATE(2026,12,31)-Assumptions!H57)/365.25)))/Assumptions!H54/Assumptions!H55*100 -> 632.30521 | E10: =((DCF!C10/(1+$A10)^DCF!C12+DCF!D10/(1+$A10)^DCF!D12+DCF!E10/(1+$A10)^DCF!E12+DCF!F10/(1+$A10)^DCF!F12+DCF!G10/(1+$A10)^DCF!G12)+((((Forecast!J40*(1+E$5))+(Forecast!J41*(1+E$5))-MAX(((Forecast!J42+Forecast!J43)*(1+E$5)),(Forecast!J41*(1+E$5))+((Forecast!J40*(1+E$5))*E$5/Assumptions!H40))-(Forecast!J6*E$5*Assumptions!G31)+(Forecast!J45*(1+E$5))+(Forecast!J46*(1+E$5))-(Forecast!J47*(1+E$5)))/($A10-E$5))/(1+$A10)^DCF!C30)+(DCF!C50-DCF!C49)+(Assumptions!H53/(1+$A10)^((DATE(2026,12,31)-Assumptions!H57)/365.25)))/Assumptions!H54/Assumptions!H55*100 -> 656.01842 | F10: =((DCF!C10/(1+$A10)^DCF!C12+DCF!D10/(1+$A10)^DCF!D12+DCF!E10/(1+$A10)^DCF!E12+DCF!F10/(1+$A10)^DCF!F12+DCF!G10/(1+$A10)^DCF!G12)+((((Forecast!J40*(1+F$5))+(Forecast!J41*(1+F$5))-MAX(((Forecast!J42+Forecast!J43)*(1+F$5)),(Forecast!J41*(1+F$5))+((Forecast!J40*(1+F$5))*F$5/Assumptions!H40))-(Forecast!J6*F$5*Assumptions!G31)+(Forecast!J45*(1+F$5))+(Forecast!J46*(1+F$5))-(Forecast!J47*(1+F$5)))/($A10-F$5))/(1+$A10)^DCF!C30)+(DCF!C50-DCF!C49)+(Assumptions!H53/(1+$A10)^((DATE(2026,12,31)-Assumptions!H57)/365.25)))/Assumptions!H54/Assumptions!H55*100 -> 683.61684 | G10: =((DCF!C10/(1+$A10)^DCF!C12+DCF!D10/(1+$A10)^DCF!D12+DCF!E10/(1+$A10)^DCF!E12+DCF!F10/(1+$A10)^DCF!F12+DCF!G10/(1+$A10)^DCF!G12)+((((Forecast!J40*(1+G$5))+(Forecast!J41*(1+G$5))-MAX(((Forecast!J42+Forecast!J43)*(1+G$5)),(Forecast!J41*(1+G$5))+((Forecast!J40*(1+G$5))*G$5/Assumptions!H40))-(Forecast!J6*G$5*Assumptions!G31)+(Forecast!J45*(1+G$5))+(Forecast!J46*(1+G$5))-(Forecast!J47*(1+G$5)))/($A10-G$5))/(1+$A10)^DCF!C30)+(DCF!C50-DCF!C49)+(Assumptions!H53/(1+$A10)^((DATE(2026,12,31)-Assumptions!H57)/365.25)))/Assumptions!H54/Assumptions!H55*100 -> 716.2533 | H10: =((DCF!C10/(1+$A10)^DCF!C12+DCF!D10/(1+$A10)^DCF!D12+DCF!E10/(1+$A10)^DCF!E12+DCF!F10/(1+$A10)^DCF!F12+DCF!G10/(1+$A10)^DCF!G12)+((((Forecast!J40*(1+H$5))+(Forecast!J41*(1+H$5))-MAX(((Forecast!J42+Forecast!J43)*(1+H$5)),(Forecast!J41*(1+H$5))+((Forecast!J40*(1+H$5))*H$5/Assumptions!H40))-(Forecast!J6*H$5*Assumptions!G31)+(Forecast!J45*(1+H$5))+(Forecast!J46*(1+H$5))-(Forecast!J47*(1+H$5)))/($A10-H$5))/(1+$A10)^DCF!C30)+(DCF!C50-DCF!C49)+(Assumptions!H53/(1+$A10)^((DATE(2026,12,31)-Assumptions!H57)/365.25)))/Assumptions!H54/Assumptions!H55*100 -> 755.58673 | J10: Cash capex | K10: % vs Base | L10: 0.05 | M10: 0 | N10: -0.03
A11: 0.080552974 | B11: =((DCF!C10/(1+$A11)^DCF!C12+DCF!D10/(1+$A11)^DCF!D12+DCF!E10/(1+$A11)^DCF!E12+DCF!F10/(1+$A11)^DCF!F12+DCF!G10/(1+$A11)^DCF!G12)+((((Forecast!J40*(1+B$5))+(Forecast!J41*(1+B$5))-MAX(((Forecast!J42+Forecast!J43)*(1+B$5)),(Forecast!J41*(1+B$5))+((Forecast!J40*(1+B$5))*B$5/Assumptions!H40))-(Forecast!J6*B$5*Assumptions!G31)+(Forecast!J45*(1+B$5))+(Forecast!J46*(1+B$5))-(Forecast!J47*(1+B$5)))/($A11-B$5))/(1+$A11)^DCF!C30)+(DCF!C50-DCF!C49)+(Assumptions!H53/(1+$A11)^((DATE(2026,12,31)-Assumptions!H57)/365.25)))/Assumptions!H54/Assumptions!H55*100 -> 537.98341 | C11: =((DCF!C10/(1+$A11)^DCF!C12+DCF!D10/(1+$A11)^DCF!D12+DCF!E10/(1+$A11)^DCF!E12+DCF!F10/(1+$A11)^DCF!F12+DCF!G10/(1+$A11)^DCF!G12)+((((Forecast!J40*(1+C$5))+(Forecast!J41*(1+C$5))-MAX(((Forecast!J42+Forecast!J43)*(1+C$5)),(Forecast!J41*(1+C$5))+((Forecast!J40*(1+C$5))*C$5/Assumptions!H40))-(Forecast!J6*C$5*Assumptions!G31)+(Forecast!J45*(1+C$5))+(Forecast!J46*(1+C$5))-(Forecast!J47*(1+C$5)))/($A11-C$5))/(1+$A11)^DCF!C30)+(DCF!C50-DCF!C49)+(Assumptions!H53/(1+$A11)^((DATE(2026,12,31)-Assumptions!H57)/365.25)))/Assumptions!H54/Assumptions!H55*100 -> 551.99248 | D11: =((DCF!C10/(1+$A11)^DCF!C12+DCF!D10/(1+$A11)^DCF!D12+DCF!E10/(1+$A11)^DCF!E12+DCF!F10/(1+$A11)^DCF!F12+DCF!G10/(1+$A11)^DCF!G12)+((((Forecast!J40*(1+D$5))+(Forecast!J41*(1+D$5))-MAX(((Forecast!J42+Forecast!J43)*(1+D$5)),(Forecast!J41*(1+D$5))+((Forecast!J40*(1+D$5))*D$5/Assumptions!H40))-(Forecast!J6*D$5*Assumptions!G31)+(Forecast!J45*(1+D$5))+(Forecast!J46*(1+D$5))-(Forecast!J47*(1+D$5)))/($A11-D$5))/(1+$A11)^DCF!C30)+(DCF!C50-DCF!C49)+(Assumptions!H53/(1+$A11)^((DATE(2026,12,31)-Assumptions!H57)/365.25)))/Assumptions!H54/Assumptions!H55*100 -> 567.69131 | E11: =((DCF!C10/(1+$A11)^DCF!C12+DCF!D10/(1+$A11)^DCF!D12+DCF!E10/(1+$A11)^DCF!E12+DCF!F10/(1+$A11)^DCF!F12+DCF!G10/(1+$A11)^DCF!G12)+((((Forecast!J40*(1+E$5))+(Forecast!J41*(1+E$5))-MAX(((Forecast!J42+Forecast!J43)*(1+E$5)),(Forecast!J41*(1+E$5))+((Forecast!J40*(1+E$5))*E$5/Assumptions!H40))-(Forecast!J6*E$5*Assumptions!G31)+(Forecast!J45*(1+E$5))+(Forecast!J46*(1+E$5))-(Forecast!J47*(1+E$5)))/($A11-E$5))/(1+$A11)^DCF!C30)+(DCF!C50-DCF!C49)+(Assumptions!H53/(1+$A11)^((DATE(2026,12,31)-Assumptions!H57)/365.25)))/Assumptions!H54/Assumptions!H55*100 -> 585.46653 | F11: =((DCF!C10/(1+$A11)^DCF!C12+DCF!D10/(1+$A11)^DCF!D12+DCF!E10/(1+$A11)^DCF!E12+DCF!F10/(1+$A11)^DCF!F12+DCF!G10/(1+$A11)^DCF!G12)+((((Forecast!J40*(1+F$5))+(Forecast!J41*(1+F$5))-MAX(((Forecast!J42+Forecast!J43)*(1+F$5)),(Forecast!J41*(1+F$5))+((Forecast!J40*(1+F$5))*F$5/Assumptions!H40))-(Forecast!J6*F$5*Assumptions!G31)+(Forecast!J45*(1+F$5))+(Forecast!J46*(1+F$5))-(Forecast!J47*(1+F$5)))/($A11-F$5))/(1+$A11)^DCF!C30)+(DCF!C50-DCF!C49)+(Assumptions!H53/(1+$A11)^((DATE(2026,12,31)-Assumptions!H57)/365.25)))/Assumptions!H54/Assumptions!H55*100 -> 605.8325 | G11: =((DCF!C10/(1+$A11)^DCF!C12+DCF!D10/(1+$A11)^DCF!D12+DCF!E10/(1+$A11)^DCF!E12+DCF!F10/(1+$A11)^DCF!F12+DCF!G10/(1+$A11)^DCF!G12)+((((Forecast!J40*(1+G$5))+(Forecast!J41*(1+G$5))-MAX(((Forecast!J42+Forecast!J43)*(1+G$5)),(Forecast!J41*(1+G$5))+((Forecast!J40*(1+G$5))*G$5/Assumptions!H40))-(Forecast!J6*G$5*Assumptions!G31)+(Forecast!J45*(1+G$5))+(Forecast!J46*(1+G$5))-(Forecast!J47*(1+G$5)))/($A11-G$5))/(1+$A11)^DCF!C30)+(DCF!C50-DCF!C49)+(Assumptions!H53/(1+$A11)^((DATE(2026,12,31)-Assumptions!H57)/365.25)))/Assumptions!H54/Assumptions!H55*100 -> 629.48877 | H11: =((DCF!C10/(1+$A11)^DCF!C12+DCF!D10/(1+$A11)^DCF!D12+DCF!E10/(1+$A11)^DCF!E12+DCF!F10/(1+$A11)^DCF!F12+DCF!G10/(1+$A11)^DCF!G12)+((((Forecast!J40*(1+H$5))+(Forecast!J41*(1+H$5))-MAX(((Forecast!J42+Forecast!J43)*(1+H$5)),(Forecast!J41*(1+H$5))+((Forecast!J40*(1+H$5))*H$5/Assumptions!H40))-(Forecast!J6*H$5*Assumptions!G31)+(Forecast!J45*(1+H$5))+(Forecast!J46*(1+H$5))-(Forecast!J47*(1+H$5)))/($A11-H$5))/(1+$A11)^DCF!C30)+(DCF!C50-DCF!C49)+(Assumptions!H53/(1+$A11)^((DATE(2026,12,31)-Assumptions!H57)/365.25)))/Assumptions!H54/Assumptions!H55*100 -> 657.41163
A12: 0.085552974 | B12: =((DCF!C10/(1+$A12)^DCF!C12+DCF!D10/(1+$A12)^DCF!D12+DCF!E10/(1+$A12)^DCF!E12+DCF!F10/(1+$A12)^DCF!F12+DCF!G10/(1+$A12)^DCF!G12)+((((Forecast!J40*(1+B$5))+(Forecast!J41*(1+B$5))-MAX(((Forecast!J42+Forecast!J43)*(1+B$5)),(Forecast!J41*(1+B$5))+((Forecast!J40*(1+B$5))*B$5/Assumptions!H40))-(Forecast!J6*B$5*Assumptions!G31)+(Forecast!J45*(1+B$5))+(Forecast!J46*(1+B$5))-(Forecast!J47*(1+B$5)))/($A12-B$5))/(1+$A12)^DCF!C30)+(DCF!C50-DCF!C49)+(Assumptions!H53/(1+$A12)^((DATE(2026,12,31)-Assumptions!H57)/365.25)))/Assumptions!H54/Assumptions!H55*100 -> 489.04936 | C12: =((DCF!C10/(1+$A12)^DCF!C12+DCF!D10/(1+$A12)^DCF!D12+DCF!E10/(1+$A12)^DCF!E12+DCF!F10/(1+$A12)^DCF!F12+DCF!G10/(1+$A12)^DCF!G12)+((((Forecast!J40*(1+C$5))+(Forecast!J41*(1+C$5))-MAX(((Forecast!J42+Forecast!J43)*(1+C$5)),(Forecast!J41*(1+C$5))+((Forecast!J40*(1+C$5))*C$5/Assumptions!H40))-(Forecast!J6*C$5*Assumptions!G31)+(Forecast!J45*(1+C$5))+(Forecast!J46*(1+C$5))-(Forecast!J47*(1+C$5)))/($A12-C$5))/(1+$A12)^DCF!C30)+(DCF!C50-DCF!C49)+(Assumptions!H53/(1+$A12)^((DATE(2026,12,31)-Assumptions!H57)/365.25)))/Assumptions!H54/Assumptions!H55*100 -> 499.77674 | D12: =((DCF!C10/(1+$A12)^DCF!C12+DCF!D10/(1+$A12)^DCF!D12+DCF!E10/(1+$A12)^DCF!E12+DCF!F10/(1+$A12)^DCF!F12+DCF!G10/(1+$A12)^DCF!G12)+((((Forecast!J40*(1+D$5))+(Forecast!J41*(1+D$5))-MAX(((Forecast!J42+Forecast!J43)*(1+D$5)),(Forecast!J41*(1+D$5))+((Forecast!J40*(1+D$5))*D$5/Assumptions!H40))-(Forecast!J6*D$5*Assumptions!G31)+(Forecast!J45*(1+D$5))+(Forecast!J46*(1+D$5))-(Forecast!J47*(1+D$5)))/($A12-D$5))/(1+$A12)^DCF!C30)+(DCF!C50-DCF!C49)+(Assumptions!H53/(1+$A12)^((DATE(2026,12,31)-Assumptions!H57)/365.25)))/Assumptions!H54/Assumptions!H55*100 -> 511.65314 | E12: =((DCF!C10/(1+$A12)^DCF!C12+DCF!D10/(1+$A12)^DCF!D12+DCF!E10/(1+$A12)^DCF!E12+DCF!F10/(1+$A12)^DCF!F12+DCF!G10/(1+$A12)^DCF!G12)+((((Forecast!J40*(1+E$5))+(Forecast!J41*(1+E$5))-MAX(((Forecast!J42+Forecast!J43)*(1+E$5)),(Forecast!J41*(1+E$5))+((Forecast!J40*(1+E$5))*E$5/Assumptions!H40))-(Forecast!J6*E$5*Assumptions!G31)+(Forecast!J45*(1+E$5))+(Forecast!J46*(1+E$5))-(Forecast!J47*(1+E$5)))/($A12-E$5))/(1+$A12)^DCF!C30)+(DCF!C50-DCF!C49)+(Assumptions!H53/(1+$A12)^((DATE(2026,12,31)-Assumptions!H57)/365.25)))/Assumptions!H54/Assumptions!H55*100 -> 524.92285 | F12: =((DCF!C10/(1+$A12)^DCF!C12+DCF!D10/(1+$A12)^DCF!D12+DCF!E10/(1+$A12)^DCF!E12+DCF!F10/(1+$A12)^DCF!F12+DCF!G10/(1+$A12)^DCF!G12)+((((Forecast!J40*(1+F$5))+(Forecast!J41*(1+F$5))-MAX(((Forecast!J42+Forecast!J43)*(1+F$5)),(Forecast!J41*(1+F$5))+((Forecast!J40*(1+F$5))*F$5/Assumptions!H40))-(Forecast!J6*F$5*Assumptions!G31)+(Forecast!J45*(1+F$5))+(Forecast!J46*(1+F$5))-(Forecast!J47*(1+F$5)))/($A12-F$5))/(1+$A12)^DCF!C30)+(DCF!C50-DCF!C49)+(Assumptions!H53/(1+$A12)^((DATE(2026,12,31)-Assumptions!H57)/365.25)))/Assumptions!H54/Assumptions!H55*100 -> 539.90469 | G12: =((DCF!C10/(1+$A12)^DCF!C12+DCF!D10/(1+$A12)^DCF!D12+DCF!E10/(1+$A12)^DCF!E12+DCF!F10/(1+$A12)^DCF!F12+DCF!G10/(1+$A12)^DCF!G12)+((((Forecast!J40*(1+G$5))+(Forecast!J41*(1+G$5))-MAX(((Forecast!J42+Forecast!J43)*(1+G$5)),(Forecast!J41*(1+G$5))+((Forecast!J40*(1+G$5))*G$5/Assumptions!H40))-(Forecast!J6*G$5*Assumptions!G31)+(Forecast!J45*(1+G$5))+(Forecast!J46*(1+G$5))-(Forecast!J47*(1+G$5)))/($A12-G$5))/(1+$A12)^DCF!C30)+(DCF!C50-DCF!C49)+(Assumptions!H53/(1+$A12)^((DATE(2026,12,31)-Assumptions!H57)/365.25)))/Assumptions!H54/Assumptions!H55*100 -> 557.02279 | H12: =((DCF!C10/(1+$A12)^DCF!C12+DCF!D10/(1+$A12)^DCF!D12+DCF!E10/(1+$A12)^DCF!E12+DCF!F10/(1+$A12)^DCF!F12+DCF!G10/(1+$A12)^DCF!G12)+((((Forecast!J40*(1+H$5))+(Forecast!J41*(1+H$5))-MAX(((Forecast!J42+Forecast!J43)*(1+H$5)),(Forecast!J41*(1+H$5))+((Forecast!J40*(1+H$5))*H$5/Assumptions!H40))-(Forecast!J6*H$5*Assumptions!G31)+(Forecast!J45*(1+H$5))+(Forecast!J46*(1+H$5))-(Forecast!J47*(1+H$5)))/($A12-H$5))/(1+$A12)^DCF!C30)+(DCF!C50-DCF!C49)+(Assumptions!H53/(1+$A12)^((DATE(2026,12,31)-Assumptions!H57)/365.25)))/Assumptions!H54/Assumptions!H55*100 -> 576.85397 | J12: SCENARIO OUTPUTS
J13: Metric | K13: Unit | L13: Bear | M13: Base | N13: Bull
J14: Enterprise value | K14: $m | L14: =L32 -> 175969.04 | M14: =M32 -> 223978.97 | N14: =N32 -> 269258.1
J15: Equity value | K15: $m | L15: =L33 -> 110373.65 | M15: =M33 -> 158383.58 | N15: =N33 -> 203662.71
J16: Implied share value | K16: GBX | L16: =L34 -> 515.18771 | M16: =M34 -> 739.28221 | N16: =N34 -> 950.63021
J17: Upside / (downside) | K17: % | L17: =L35 -> -0.04541836 | M17: =M35 -> 0.36980212 | N17: =N35 -> 0.76140487
J20: SCENARIO CASH-FLOW ENGINE
J21: Metric | K21: Unit | L21: Bear | M21: Base | N21: Bull
J22: 2026E UFCF | K22: $m | L22: =(((((((Forecast!F17*(1+$L$6)*(1+$L$7))*Assumptions!C10)-(Forecast!F19*(1+$L$7))-Forecast!F20)+(((Forecast!F23*(1+$L$8)*(1+$L$7))*Assumptions!C18)-(Forecast!F25*(1+$L$7))-Forecast!F26)+(Forecast!F28*(1+$L$9))+Forecast!F29+Forecast!F30)-Forecast!F35-Forecast!F36)*(1-Forecast!F38))+((Forecast!F19*(1+$L$7))+(Forecast!F25*(1+$L$7))+Assumptions!C28)-(Forecast!F42*(1+$L$10))-Forecast!F43-Forecast!F44+Forecast!F45+Forecast!F46-Forecast!F47) -> 8180.8352 | M22: =(((((((Forecast!F17*(1+$M$6)*(1+$M$7))*Assumptions!C10)-(Forecast!F19*(1+$M$7))-Forecast!F20)+(((Forecast!F23*(1+$M$8)*(1+$M$7))*Assumptions!C18)-(Forecast!F25*(1+$M$7))-Forecast!F26)+(Forecast!F28*(1+$M$9))+Forecast!F29+Forecast!F30)-Forecast!F35-Forecast!F36)*(1-Forecast!F38))+((Forecast!F19*(1+$M$7))+(Forecast!F25*(1+$M$7))+Assumptions!C28)-(Forecast!F42*(1+$M$10))-Forecast!F43-Forecast!F44+Forecast!F45+Forecast!F46-Forecast!F47) -> 12657.783 | N22: =(((((((Forecast!F17*(1+$N$6)*(1+$N$7))*Assumptions!C10)-(Forecast!F19*(1+$N$7))-Forecast!F20)+(((Forecast!F23*(1+$N$8)*(1+$N$7))*Assumptions!C18)-(Forecast!F25*(1+$N$7))-Forecast!F26)+(Forecast!F28*(1+$N$9))+Forecast!F29+Forecast!F30)-Forecast!F35-Forecast!F36)*(1-Forecast!F38))+((Forecast!F19*(1+$N$7))+(Forecast!F25*(1+$N$7))+Assumptions!C28)-(Forecast!F42*(1+$N$10))-Forecast!F43-Forecast!F44+Forecast!F45+Forecast!F46-Forecast!F47) -> 16603.983
J23: 2027E UFCF | K23: $m | L23: =(((((((Forecast!G17*(1+$L$6)*(1+$L$7))*Assumptions!D10)-(Forecast!G19*(1+$L$7))-Forecast!G20)+(((Forecast!G23*(1+$L$8)*(1+$L$7))*Assumptions!D18)-(Forecast!G25*(1+$L$7))-Forecast!G26)+(Forecast!G28*(1+$L$9))+Forecast!G29+Forecast!G30)-Forecast!G35-Forecast!G36)*(1-Forecast!G38))+((Forecast!G19*(1+$L$7))+(Forecast!G25*(1+$L$7))+Assumptions!D28)-(Forecast!G42*(1+$L$10))-Forecast!G43-Forecast!G44+Forecast!G45+Forecast!G46-Forecast!G47) -> 10325.162 | M23: =(((((((Forecast!G17*(1+$M$6)*(1+$M$7))*Assumptions!D10)-(Forecast!G19*(1+$M$7))-Forecast!G20)+(((Forecast!G23*(1+$M$8)*(1+$M$7))*Assumptions!D18)-(Forecast!G25*(1+$M$7))-Forecast!G26)+(Forecast!G28*(1+$M$9))+Forecast!G29+Forecast!G30)-Forecast!G35-Forecast!G36)*(1-Forecast!G38))+((Forecast!G19*(1+$M$7))+(Forecast!G25*(1+$M$7))+Assumptions!D28)-(Forecast!G42*(1+$M$10))-Forecast!G43-Forecast!G44+Forecast!G45+Forecast!G46-Forecast!G47) -> 13884.253 | N23: =(((((((Forecast!G17*(1+$N$6)*(1+$N$7))*Assumptions!D10)-(Forecast!G19*(1+$N$7))-Forecast!G20)+(((Forecast!G23*(1+$N$8)*(1+$N$7))*Assumptions!D18)-(Forecast!G25*(1+$N$7))-Forecast!G26)+(Forecast!G28*(1+$N$9))+Forecast!G29+Forecast!G30)-Forecast!G35-Forecast!G36)*(1-Forecast!G38))+((Forecast!G19*(1+$N$7))+(Forecast!G25*(1+$N$7))+Assumptions!D28)-(Forecast!G42*(1+$N$10))-Forecast!G43-Forecast!G44+Forecast!G45+Forecast!G46-Forecast!G47) -> 17030.277
J24: 2028E UFCF | K24: $m | L24: =(((((((Forecast!H17*(1+$L$6)*(1+$L$7))*Assumptions!E10)-(Forecast!H19*(1+$L$7))-Forecast!H20)+(((Forecast!H23*(1+$L$8)*(1+$L$7))*Assumptions!E18)-(Forecast!H25*(1+$L$7))-Forecast!H26)+(Forecast!H28*(1+$L$9))+Forecast!H29+Forecast!H30)-Forecast!H35-Forecast!H36)*(1-Forecast!H38))+((Forecast!H19*(1+$L$7))+(Forecast!H25*(1+$L$7))+Assumptions!E28)-(Forecast!H42*(1+$L$10))-Forecast!H43-Forecast!H44+Forecast!H45+Forecast!H46-Forecast!H47) -> 9039.3757 | M24: =(((((((Forecast!H17*(1+$M$6)*(1+$M$7))*Assumptions!E10)-(Forecast!H19*(1+$M$7))-Forecast!H20)+(((Forecast!H23*(1+$M$8)*(1+$M$7))*Assumptions!E18)-(Forecast!H25*(1+$M$7))-Forecast!H26)+(Forecast!H28*(1+$M$9))+Forecast!H29+Forecast!H30)-Forecast!H35-Forecast!H36)*(1-Forecast!H38))+((Forecast!H19*(1+$M$7))+(Forecast!H25*(1+$M$7))+Assumptions!E28)-(Forecast!H42*(1+$M$10))-Forecast!H43-Forecast!H44+Forecast!H45+Forecast!H46-Forecast!H47) -> 12589.171 | N24: =(((((((Forecast!H17*(1+$N$6)*(1+$N$7))*Assumptions!E10)-(Forecast!H19*(1+$N$7))-Forecast!H20)+(((Forecast!H23*(1+$N$8)*(1+$N$7))*Assumptions!E18)-(Forecast!H25*(1+$N$7))-Forecast!H26)+(Forecast!H28*(1+$N$9))+Forecast!H29+Forecast!H30)-Forecast!H35-Forecast!H36)*(1-Forecast!H38))+((Forecast!H19*(1+$N$7))+(Forecast!H25*(1+$N$7))+Assumptions!E28)-(Forecast!H42*(1+$N$10))-Forecast!H43-Forecast!H44+Forecast!H45+Forecast!H46-Forecast!H47) -> 15755.546
J25: 2029E UFCF | K25: $m | L25: =(((((((Forecast!I17*(1+$L$6)*(1+$L$7))*Assumptions!F10)-(Forecast!I19*(1+$L$7))-Forecast!I20)+(((Forecast!I23*(1+$L$8)*(1+$L$7))*Assumptions!F18)-(Forecast!I25*(1+$L$7))-Forecast!I26)+(Forecast!I28*(1+$L$9))+Forecast!I29+Forecast!I30)-Forecast!I35-Forecast!I36)*(1-Forecast!I38))+((Forecast!I19*(1+$L$7))+(Forecast!I25*(1+$L$7))+Assumptions!F28)-(Forecast!I42*(1+$L$10))-Forecast!I43-Forecast!I44+Forecast!I45+Forecast!I46-Forecast!I47) -> 9742.5419 | M25: =(((((((Forecast!I17*(1+$M$6)*(1+$M$7))*Assumptions!F10)-(Forecast!I19*(1+$M$7))-Forecast!I20)+(((Forecast!I23*(1+$M$8)*(1+$M$7))*Assumptions!F18)-(Forecast!I25*(1+$M$7))-Forecast!I26)+(Forecast!I28*(1+$M$9))+Forecast!I29+Forecast!I30)-Forecast!I35-Forecast!I36)*(1-Forecast!I38))+((Forecast!I19*(1+$M$7))+(Forecast!I25*(1+$M$7))+Assumptions!F28)-(Forecast!I42*(1+$M$10))-Forecast!I43-Forecast!I44+Forecast!I45+Forecast!I46-Forecast!I47) -> 13450.78 | N25: =(((((((Forecast!I17*(1+$N$6)*(1+$N$7))*Assumptions!F10)-(Forecast!I19*(1+$N$7))-Forecast!I20)+(((Forecast!I23*(1+$N$8)*(1+$N$7))*Assumptions!F18)-(Forecast!I25*(1+$N$7))-Forecast!I26)+(Forecast!I28*(1+$N$9))+Forecast!I29+Forecast!I30)-Forecast!I35-Forecast!I36)*(1-Forecast!I38))+((Forecast!I19*(1+$N$7))+(Forecast!I25*(1+$N$7))+Assumptions!F28)-(Forecast!I42*(1+$N$10))-Forecast!I43-Forecast!I44+Forecast!I45+Forecast!I46-Forecast!I47) -> 16780.484
J26: 2030E UFCF | K26: $m | L26: =(((((((Forecast!J17*(1+$L$6)*(1+$L$7))*Assumptions!G10)-(Forecast!J19*(1+$L$7))-Forecast!J20)+(((Forecast!J23*(1+$L$8)*(1+$L$7))*Assumptions!G18)-(Forecast!J25*(1+$L$7))-Forecast!J26)+(Forecast!J28*(1+$L$9))+Forecast!J29+Forecast!J30)-Forecast!J35-Forecast!J36)*(1-Forecast!J38))+((Forecast!J19*(1+$L$7))+(Forecast!J25*(1+$L$7))+Assumptions!G28)-(Forecast!J42*(1+$L$10))-Forecast!J43-Forecast!J44+Forecast!J45+Forecast!J46-Forecast!J47) -> 11306.524 | M26: =(((((((Forecast!J17*(1+$M$6)*(1+$M$7))*Assumptions!G10)-(Forecast!J19*(1+$M$7))-Forecast!J20)+(((Forecast!J23*(1+$M$8)*(1+$M$7))*Assumptions!G18)-(Forecast!J25*(1+$M$7))-Forecast!J26)+(Forecast!J28*(1+$M$9))+Forecast!J29+Forecast!J30)-Forecast!J35-Forecast!J36)*(1-Forecast!J38))+((Forecast!J19*(1+$M$7))+(Forecast!J25*(1+$M$7))+Assumptions!G28)-(Forecast!J42*(1+$M$10))-Forecast!J43-Forecast!J44+Forecast!J45+Forecast!J46-Forecast!J47) -> 15205.398 | N26: =(((((((Forecast!J17*(1+$N$6)*(1+$N$7))*Assumptions!G10)-(Forecast!J19*(1+$N$7))-Forecast!J20)+(((Forecast!J23*(1+$N$8)*(1+$N$7))*Assumptions!G18)-(Forecast!J25*(1+$N$7))-Forecast!J26)+(Forecast!J28*(1+$N$9))+Forecast!J29+Forecast!J30)-Forecast!J35-Forecast!J36)*(1-Forecast!J38))+((Forecast!J19*(1+$N$7))+(Forecast!J25*(1+$N$7))+Assumptions!G28)-(Forecast!J42*(1+$N$10))-Forecast!J43-Forecast!J44+Forecast!J45+Forecast!J46-Forecast!J47) -> 18732.093
J28: 2030 NOPAT | K28: $m | L28: =((((((Forecast!J17*(1+$L$6)*(1+$L$7))*Assumptions!G10)-(Forecast!J19*(1+$L$7))-Forecast!J20)+(((Forecast!J23*(1+$L$8)*(1+$L$7))*Assumptions!G18)-(Forecast!J25*(1+$L$7))-Forecast!J26)+(Forecast!J28*(1+$L$9))+Forecast!J29+Forecast!J30)-Forecast!J35-Forecast!J36)*(1-Forecast!J38)) -> 9683.0299 | M28: =((((((Forecast!J17*(1+$M$6)*(1+$M$7))*Assumptions!G10)-(Forecast!J19*(1+$M$7))-Forecast!J20)+(((Forecast!J23*(1+$M$8)*(1+$M$7))*Assumptions!G18)-(Forecast!J25*(1+$M$7))-Forecast!J26)+(Forecast!J28*(1+$M$9))+Forecast!J29+Forecast!J30)-Forecast!J35-Forecast!J36)*(1-Forecast!J38)) -> 12502.405 | N28: =((((((Forecast!J17*(1+$N$6)*(1+$N$7))*Assumptions!G10)-(Forecast!J19*(1+$N$7))-Forecast!J20)+(((Forecast!J23*(1+$N$8)*(1+$N$7))*Assumptions!G18)-(Forecast!J25*(1+$N$7))-Forecast!J26)+(Forecast!J28*(1+$N$9))+Forecast!J29+Forecast!J30)-Forecast!J35-Forecast!J36)*(1-Forecast!J38)) -> 15229.6
J29: 2030 D&A | K29: $m | L29: =((Forecast!J19*(1+$L$7))+(Forecast!J25*(1+$L$7))+Assumptions!G28) -> 17619.86 | M29: =((Forecast!J19*(1+$M$7))+(Forecast!J25*(1+$M$7))+Assumptions!G28) -> 17999.36 | N29: =((Forecast!J19*(1+$N$7))+(Forecast!J25*(1+$N$7))+Assumptions!G28) -> 18378.859
J30: 2030 cash capex | K30: $m | L30: =(Forecast!J42*(1+$L$10)) -> 14700 | M30: =(Forecast!J42*(1+$M$10)) -> 14000 | N30: =(Forecast!J42*(1+$N$10)) -> 13580
J31: Terminal UFCF | K31: $m | L31: =((L28*(1+Assumptions!H39))+(L29*(1+Assumptions!H39))-MAX(((L30+Forecast!J43)*(1+Assumptions!H39)),(L29*(1+Assumptions!H39))+((L28*(1+Assumptions!H39))*Assumptions!H39/Assumptions!H40))-(Forecast!J6*Assumptions!H39*Assumptions!G31)+(Forecast!J45*(1+Assumptions!H39))+(Forecast!J46*(1+Assumptions!H39))-(Forecast!J47*(1+Assumptions!H39))) -> 10382.983 | M31: =((M28*(1+Assumptions!H39))+(M29*(1+Assumptions!H39))-MAX(((M30+Forecast!J43)*(1+Assumptions!H39)),(M29*(1+Assumptions!H39))+((M28*(1+Assumptions!H39))*Assumptions!H39/Assumptions!H40))-(Forecast!J6*Assumptions!H39*Assumptions!G31)+(Forecast!J45*(1+Assumptions!H39))+(Forecast!J46*(1+Assumptions!H39))-(Forecast!J47*(1+Assumptions!H39))) -> 12815.399 | N31: =((N28*(1+Assumptions!H39))+(N29*(1+Assumptions!H39))-MAX(((N30+Forecast!J43)*(1+Assumptions!H39)),(N29*(1+Assumptions!H39))+((N28*(1+Assumptions!H39))*Assumptions!H39/Assumptions!H40))-(Forecast!J6*Assumptions!H39*Assumptions!G31)+(Forecast!J45*(1+Assumptions!H39))+(Forecast!J46*(1+Assumptions!H39))-(Forecast!J47*(1+Assumptions!H39))) -> 15168.287
J32: Enterprise value | K32: $m | L32: =(((L22-Support!C28)*DCF!C9)/(1+Assumptions!C51)^DCF!C12+L23/(1+Assumptions!C51)^DCF!D12+L24/(1+Assumptions!C51)^DCF!E12+L25/(1+Assumptions!C51)^DCF!F12+L26/(1+Assumptions!C51)^DCF!G12)+((L31/(Assumptions!C51-Assumptions!H39))/(1+Assumptions!C51)^DCF!C30) -> 175969.04 | M32: =(((M22-Support!C28)*DCF!C9)/(1+Assumptions!C51)^DCF!C12+M23/(1+Assumptions!C51)^DCF!D12+M24/(1+Assumptions!C51)^DCF!E12+M25/(1+Assumptions!C51)^DCF!F12+M26/(1+Assumptions!C51)^DCF!G12)+((M31/(Assumptions!C51-Assumptions!H39))/(1+Assumptions!C51)^DCF!C30) -> 223978.97 | N32: =(((N22-Support!C28)*DCF!C9)/(1+Assumptions!C51)^DCF!C12+N23/(1+Assumptions!C51)^DCF!D12+N24/(1+Assumptions!C51)^DCF!E12+N25/(1+Assumptions!C51)^DCF!F12+N26/(1+Assumptions!C51)^DCF!G12)+((N31/(Assumptions!C51-Assumptions!H39))/(1+Assumptions!C51)^DCF!C30) -> 269258.1
J33: Equity value | K33: $m | L33: =L32+DCF!C50 -> 110373.65 | M33: =M32+DCF!C50 -> 158383.58 | N33: =N32+DCF!C50 -> 203662.71
J34: Implied share value | K34: GBX | L34: =L33/Assumptions!H54/Assumptions!H55*100 -> 515.18771 | M34: =M33/Assumptions!H54/Assumptions!H55*100 -> 739.28221 | N34: =N33/Assumptions!H54/Assumptions!H55*100 -> 950.63021
J35: Upside / (downside) | K35: % | L35: =L34/Assumptions!H56-1 -> -0.04541836 | M35: =M34/Assumptions!H56-1 -> 0.36980212 | N35: =N34/Assumptions!H56-1 -> 0.76140487

Sheet Support
A1: BP plc | Support Schedules
A2: 2026 H1 actual / H2 estimate bridge and compact calculation support
A4: 2026 H1 / H2 CALIBRATION
A5: Metric | B5: Unit | C5: H1 2026A | D5: H2 2026E | E5: FY26E | F5: Source
A6: Sales and other operating revenues | B6: $m | C6: 121360 | D6: 109293.66 | E6: =C6+D6 -> 230653.66 | F6: S02
